2022-03-23 10:22:09,878 ERROR Invalid HTTP_HOST header: '127.0.0.1:8000'. You may need to add '127.0.0.1' to ALLOWED_HOSTS.
2022-03-23 10:22:10,191 ERROR Invalid HTTP_HOST header: '127.0.0.1:8000'. You may need to add '127.0.0.1' to ALLOWED_HOSTS.
2022-03-23 10:22:10,192 ERROR Invalid HTTP_HOST header: '127.0.0.1:8000'. You may need to add '127.0.0.1' to ALLOWED_HOSTS.
2022-03-23 10:22:24,292 ERROR Invalid HTTP_HOST header: '127.0.0.1:8000'. You may need to add '127.0.0.1' to ALLOWED_HOSTS.
2022-03-23 10:22:59,220 ERROR Invalid HTTP_HOST header: '127.0.0.1:8000'. You may need to add '127.0.0.1' to ALLOWED_HOSTS.
2022-03-23 10:23:04,982 ERROR Invalid HTTP_HOST header: '127.0.0.1:8000'. You may need to add '127.0.0.1' to ALLOWED_HOSTS.
2022-03-23 10:23:04,982 ERROR Invalid HTTP_HOST header: '127.0.0.1:8000'. You may need to add '127.0.0.1' to ALLOWED_HOSTS.
2022-03-23 10:23:07,951 ERROR Invalid HTTP_HOST header: '127.0.0.1:8000'. You may need to add '127.0.0.1' to ALLOWED_HOSTS.
2022-03-23 10:23:08,042 ERROR Invalid HTTP_HOST header: '127.0.0.1:8000'. You may need to add '127.0.0.1' to ALLOWED_HOSTS.
2022-03-23 10:24:33,391 ERROR Invalid HTTP_HOST header: '127.0.0.1:8000'. You may need to add '127.0.0.1' to ALLOWED_HOSTS.
2022-03-23 10:24:33,498 ERROR Invalid HTTP_HOST header: '127.0.0.1:8000'. You may need to add '127.0.0.1' to ALLOWED_HOSTS.
2022-03-23 10:24:35,039 ERROR Invalid HTTP_HOST header: '127.0.0.1:8000'. You may need to add '127.0.0.1' to ALLOWED_HOSTS.
2022-03-23 10:24:37,405 ERROR Invalid HTTP_HOST header: '127.0.0.1:8000'. You may need to add '127.0.0.1' to ALLOWED_HOSTS.
2022-03-23 10:24:40,075 ERROR Invalid HTTP_HOST header: '127.0.0.1:8000'. You may need to add '127.0.0.1' to ALLOWED_HOSTS.
2022-03-23 10:24:40,146 ERROR Invalid HTTP_HOST header: '127.0.0.1:8000'. You may need to add '127.0.0.1' to ALLOWED_HOSTS.
2022-03-23 10:25:13,112 ERROR Internal Server Error: /api/get_user/
Traceback (most recent call last):
  File "/home/pavi/.local/lib/python3.8/site-packages/django/core/handlers/exception.py", line 34, in inner
    response = get_response(request)
  File "/home/pavi/.local/lib/python3.8/site-packages/django/core/handlers/base.py", line 115, in _get_response
    response = self.process_exception_by_middleware(e, request)
  File "/home/pavi/.local/lib/python3.8/site-packages/django/core/handlers/base.py", line 113, in _get_response
    response = wrapped_callback(request, *callback_args, **callback_kwargs)
  File "/home/pavi/.local/lib/python3.8/site-packages/django/views/decorators/csrf.py", line 54, in wrapped_view
    return view_func(*args, **kwargs)
  File "/home/pavi/.local/lib/python3.8/site-packages/django/views/generic/base.py", line 71, in view
    return self.dispatch(request, *args, **kwargs)
  File "/home/pavi/.local/lib/python3.8/site-packages/rest_framework/views.py", line 505, in dispatch
    response = self.handle_exception(exc)
  File "/home/pavi/.local/lib/python3.8/site-packages/rest_framework/views.py", line 465, in handle_exception
    self.raise_uncaught_exception(exc)
  File "/home/pavi/.local/lib/python3.8/site-packages/rest_framework/views.py", line 476, in raise_uncaught_exception
    raise exc
  File "/home/pavi/.local/lib/python3.8/site-packages/rest_framework/views.py", line 502, in dispatch
    response = handler(request, *args, **kwargs)
  File "/home/pavi/.local/lib/python3.8/site-packages/rest_framework/decorators.py", line 50, in handler
    return func(*args, **kwargs)
  File "/home/pavi/SolarSPELL/content-curation/backend/views.py", line 171, in get_user
    return build_response({
  File "/home/pavi/SolarSPELL/content-curation/backend/standardize_format.py", line 18, in build_response
    console.log('build_response' +data +' error' + error)
NameError: name 'console' is not defined
2022-03-23 10:25:13,113 ERROR "GET /api/get_user/ HTTP/1.1" 500 20088
2022-03-23 10:25:14,798 ERROR Internal Server Error: /api/get_user/
Traceback (most recent call last):
  File "/home/pavi/.local/lib/python3.8/site-packages/django/core/handlers/exception.py", line 34, in inner
    response = get_response(request)
  File "/home/pavi/.local/lib/python3.8/site-packages/django/core/handlers/base.py", line 115, in _get_response
    response = self.process_exception_by_middleware(e, request)
  File "/home/pavi/.local/lib/python3.8/site-packages/django/core/handlers/base.py", line 113, in _get_response
    response = wrapped_callback(request, *callback_args, **callback_kwargs)
  File "/home/pavi/.local/lib/python3.8/site-packages/django/views/decorators/csrf.py", line 54, in wrapped_view
    return view_func(*args, **kwargs)
  File "/home/pavi/.local/lib/python3.8/site-packages/django/views/generic/base.py", line 71, in view
    return self.dispatch(request, *args, **kwargs)
  File "/home/pavi/.local/lib/python3.8/site-packages/rest_framework/views.py", line 505, in dispatch
    response = self.handle_exception(exc)
  File "/home/pavi/.local/lib/python3.8/site-packages/rest_framework/views.py", line 465, in handle_exception
    self.raise_uncaught_exception(exc)
  File "/home/pavi/.local/lib/python3.8/site-packages/rest_framework/views.py", line 476, in raise_uncaught_exception
    raise exc
  File "/home/pavi/.local/lib/python3.8/site-packages/rest_framework/views.py", line 502, in dispatch
    response = handler(request, *args, **kwargs)
  File "/home/pavi/.local/lib/python3.8/site-packages/rest_framework/decorators.py", line 50, in handler
    return func(*args, **kwargs)
  File "/home/pavi/SolarSPELL/content-curation/backend/views.py", line 171, in get_user
    return build_response({
  File "/home/pavi/SolarSPELL/content-curation/backend/standardize_format.py", line 18, in build_response
    console.log('build_response' +data +' error' + error)
NameError: name 'console' is not defined
2022-03-23 10:25:14,799 ERROR "GET /api/get_user/ HTTP/1.1" 500 20088
2022-03-23 10:25:30,990 ERROR Internal Server Error: /api/get_user/
Traceback (most recent call last):
  File "/home/pavi/.local/lib/python3.8/site-packages/django/core/handlers/exception.py", line 34, in inner
    response = get_response(request)
  File "/home/pavi/.local/lib/python3.8/site-packages/django/core/handlers/base.py", line 115, in _get_response
    response = self.process_exception_by_middleware(e, request)
  File "/home/pavi/.local/lib/python3.8/site-packages/django/core/handlers/base.py", line 113, in _get_response
    response = wrapped_callback(request, *callback_args, **callback_kwargs)
  File "/home/pavi/.local/lib/python3.8/site-packages/django/views/decorators/csrf.py", line 54, in wrapped_view
    return view_func(*args, **kwargs)
  File "/home/pavi/.local/lib/python3.8/site-packages/django/views/generic/base.py", line 71, in view
    return self.dispatch(request, *args, **kwargs)
  File "/home/pavi/.local/lib/python3.8/site-packages/rest_framework/views.py", line 505, in dispatch
    response = self.handle_exception(exc)
  File "/home/pavi/.local/lib/python3.8/site-packages/rest_framework/views.py", line 465, in handle_exception
    self.raise_uncaught_exception(exc)
  File "/home/pavi/.local/lib/python3.8/site-packages/rest_framework/views.py", line 476, in raise_uncaught_exception
    raise exc
  File "/home/pavi/.local/lib/python3.8/site-packages/rest_framework/views.py", line 502, in dispatch
    response = handler(request, *args, **kwargs)
  File "/home/pavi/.local/lib/python3.8/site-packages/rest_framework/decorators.py", line 50, in handler
    return func(*args, **kwargs)
  File "/home/pavi/SolarSPELL/content-curation/backend/views.py", line 171, in get_user
    return build_response({
  File "/home/pavi/SolarSPELL/content-curation/backend/standardize_format.py", line 18, in build_response
    console.log('build_response' +data +' error' + error)
NameError: name 'console' is not defined
2022-03-23 10:25:30,991 ERROR "GET /api/get_user/ HTTP/1.1" 500 20353
2022-03-23 10:25:33,926 ERROR Internal Server Error: /api/get_user/
Traceback (most recent call last):
  File "/home/pavi/.local/lib/python3.8/site-packages/django/core/handlers/exception.py", line 34, in inner
    response = get_response(request)
  File "/home/pavi/.local/lib/python3.8/site-packages/django/core/handlers/base.py", line 115, in _get_response
    response = self.process_exception_by_middleware(e, request)
  File "/home/pavi/.local/lib/python3.8/site-packages/django/core/handlers/base.py", line 113, in _get_response
    response = wrapped_callback(request, *callback_args, **callback_kwargs)
  File "/home/pavi/.local/lib/python3.8/site-packages/django/views/decorators/csrf.py", line 54, in wrapped_view
    return view_func(*args, **kwargs)
  File "/home/pavi/.local/lib/python3.8/site-packages/django/views/generic/base.py", line 71, in view
    return self.dispatch(request, *args, **kwargs)
  File "/home/pavi/.local/lib/python3.8/site-packages/rest_framework/views.py", line 505, in dispatch
    response = self.handle_exception(exc)
  File "/home/pavi/.local/lib/python3.8/site-packages/rest_framework/views.py", line 465, in handle_exception
    self.raise_uncaught_exception(exc)
  File "/home/pavi/.local/lib/python3.8/site-packages/rest_framework/views.py", line 476, in raise_uncaught_exception
    raise exc
  File "/home/pavi/.local/lib/python3.8/site-packages/rest_framework/views.py", line 502, in dispatch
    response = handler(request, *args, **kwargs)
  File "/home/pavi/.local/lib/python3.8/site-packages/rest_framework/decorators.py", line 50, in handler
    return func(*args, **kwargs)
  File "/home/pavi/SolarSPELL/content-curation/backend/views.py", line 171, in get_user
    return build_response({
  File "/home/pavi/SolarSPELL/content-curation/backend/standardize_format.py", line 18, in build_response
    console.log('build_response' +data +' error' + error)
NameError: name 'console' is not defined
2022-03-23 10:25:33,926 ERROR "GET /api/get_user/ HTTP/1.1" 500 20511
2022-03-23 10:28:08,321 ERROR Internal Server Error: /api/copyright/
Traceback (most recent call last):
  File "/home/pavi/SolarSPELL/content-curation/backend/views.py", line 48, in create
    serializer.is_valid(raise_exception=True)
  File "/home/pavi/.local/lib/python3.8/site-packages/rest_framework/serializers.py", line 242, in is_valid
    raise ValidationError(self.errors)
rest_framework.exceptions.ValidationError: {'organization': [ErrorDetail(string='Invalid pk "0" - object does not exist.', code='does_not_exist')]}

During handling of the above exception, another exception occurred:

Traceback (most recent call last):
  File "/home/pavi/.local/lib/python3.8/site-packages/django/core/handlers/exception.py", line 34, in inner
    response = get_response(request)
  File "/home/pavi/.local/lib/python3.8/site-packages/django/core/handlers/base.py", line 115, in _get_response
    response = self.process_exception_by_middleware(e, request)
  File "/home/pavi/.local/lib/python3.8/site-packages/django/core/handlers/base.py", line 113, in _get_response
    response = wrapped_callback(request, *callback_args, **callback_kwargs)
  File "/home/pavi/.local/lib/python3.8/site-packages/django/views/decorators/csrf.py", line 54, in wrapped_view
    return view_func(*args, **kwargs)
  File "/home/pavi/.local/lib/python3.8/site-packages/rest_framework/viewsets.py", line 114, in view
    return self.dispatch(request, *args, **kwargs)
  File "/home/pavi/.local/lib/python3.8/site-packages/rest_framework/views.py", line 505, in dispatch
    response = self.handle_exception(exc)
  File "/home/pavi/.local/lib/python3.8/site-packages/rest_framework/views.py", line 465, in handle_exception
    self.raise_uncaught_exception(exc)
  File "/home/pavi/.local/lib/python3.8/site-packages/rest_framework/views.py", line 476, in raise_uncaught_exception
    raise exc
  File "/home/pavi/.local/lib/python3.8/site-packages/rest_framework/views.py", line 502, in dispatch
    response = handler(request, *args, **kwargs)
  File "/home/pavi/SolarSPELL/content-curation/backend/views.py", line 63, in create
    logger.error(request+''+exec)
TypeError: unsupported operand type(s) for +: 'Request' and 'str'
2022-03-23 10:28:08,322 ERROR "POST /api/copyright/ HTTP/1.1" 500 20783
2022-03-23 10:29:35,849 ERROR Internal Server Error: /api/copyright/
Traceback (most recent call last):
  File "/home/pavi/SolarSPELL/content-curation/backend/views.py", line 48, in create
    serializer.is_valid(raise_exception=True)
  File "/home/pavi/.local/lib/python3.8/site-packages/rest_framework/serializers.py", line 242, in is_valid
    raise ValidationError(self.errors)
rest_framework.exceptions.ValidationError: {'user': [ErrorDetail(string='Invalid pk "0" - object does not exist.', code='does_not_exist')]}

During handling of the above exception, another exception occurred:

Traceback (most recent call last):
  File "/home/pavi/.local/lib/python3.8/site-packages/django/core/handlers/exception.py", line 34, in inner
    response = get_response(request)
  File "/home/pavi/.local/lib/python3.8/site-packages/django/core/handlers/base.py", line 115, in _get_response
    response = self.process_exception_by_middleware(e, request)
  File "/home/pavi/.local/lib/python3.8/site-packages/django/core/handlers/base.py", line 113, in _get_response
    response = wrapped_callback(request, *callback_args, **callback_kwargs)
  File "/home/pavi/.local/lib/python3.8/site-packages/django/views/decorators/csrf.py", line 54, in wrapped_view
    return view_func(*args, **kwargs)
  File "/home/pavi/.local/lib/python3.8/site-packages/rest_framework/viewsets.py", line 114, in view
    return self.dispatch(request, *args, **kwargs)
  File "/home/pavi/.local/lib/python3.8/site-packages/rest_framework/views.py", line 505, in dispatch
    response = self.handle_exception(exc)
  File "/home/pavi/.local/lib/python3.8/site-packages/rest_framework/views.py", line 465, in handle_exception
    self.raise_uncaught_exception(exc)
  File "/home/pavi/.local/lib/python3.8/site-packages/rest_framework/views.py", line 476, in raise_uncaught_exception
    raise exc
  File "/home/pavi/.local/lib/python3.8/site-packages/rest_framework/views.py", line 502, in dispatch
    response = handler(request, *args, **kwargs)
  File "/home/pavi/SolarSPELL/content-curation/backend/views.py", line 64, in create
    response = standard_exception_handler(request, exc)
NameError: name 'standard_exception_handler' is not defined
2022-03-23 10:29:35,850 ERROR "POST /api/copyright/ HTTP/1.1" 500 20785
2022-03-23 10:40:57,677 ERROR Internal Server Error: /api/copyright/
Traceback (most recent call last):
  File "/home/pavi/.local/lib/python3.8/site-packages/django/core/handlers/exception.py", line 34, in inner
    response = get_response(request)
  File "/home/pavi/.local/lib/python3.8/site-packages/django/core/handlers/base.py", line 115, in _get_response
    response = self.process_exception_by_middleware(e, request)
  File "/home/pavi/.local/lib/python3.8/site-packages/django/core/handlers/base.py", line 113, in _get_response
    response = wrapped_callback(request, *callback_args, **callback_kwargs)
  File "/home/pavi/.local/lib/python3.8/site-packages/django/views/decorators/csrf.py", line 54, in wrapped_view
    return view_func(*args, **kwargs)
  File "/home/pavi/.local/lib/python3.8/site-packages/rest_framework/viewsets.py", line 114, in view
    return self.dispatch(request, *args, **kwargs)
  File "/home/pavi/.local/lib/python3.8/site-packages/rest_framework/views.py", line 507, in dispatch
    self.response = self.finalize_response(request, response, *args, **kwargs)
  File "/home/pavi/.local/lib/python3.8/site-packages/rest_framework/views.py", line 419, in finalize_response
    assert isinstance(response, HttpResponseBase), (
AssertionError: Expected a `Response`, `HttpResponse` or `HttpStreamingResponse` to be returned from the view, but received a `<class 'NoneType'>`
2022-03-23 10:40:57,678 ERROR "POST /api/copyright/ HTTP/1.1" 500 92721
2022-03-23 10:42:37,473 ERROR Internal Server Error: /api/copyright/
Traceback (most recent call last):
  File "/home/pavi/.local/lib/python3.8/site-packages/django/core/handlers/exception.py", line 34, in inner
    response = get_response(request)
  File "/home/pavi/.local/lib/python3.8/site-packages/django/core/handlers/base.py", line 115, in _get_response
    response = self.process_exception_by_middleware(e, request)
  File "/home/pavi/.local/lib/python3.8/site-packages/django/core/handlers/base.py", line 113, in _get_response
    response = wrapped_callback(request, *callback_args, **callback_kwargs)
  File "/home/pavi/.local/lib/python3.8/site-packages/django/views/decorators/csrf.py", line 54, in wrapped_view
    return view_func(*args, **kwargs)
  File "/home/pavi/.local/lib/python3.8/site-packages/rest_framework/viewsets.py", line 114, in view
    return self.dispatch(request, *args, **kwargs)
  File "/home/pavi/.local/lib/python3.8/site-packages/rest_framework/views.py", line 507, in dispatch
    self.response = self.finalize_response(request, response, *args, **kwargs)
  File "/home/pavi/.local/lib/python3.8/site-packages/rest_framework/views.py", line 419, in finalize_response
    assert isinstance(response, HttpResponseBase), (
AssertionError: Expected a `Response`, `HttpResponse` or `HttpStreamingResponse` to be returned from the view, but received a `<class 'NoneType'>`
2022-03-23 10:42:37,474 ERROR "POST /api/copyright/ HTTP/1.1" 500 92721
2022-03-23 11:20:58,804 ERROR Internal Server Error: /api/copyright/
Traceback (most recent call last):
  File "/home/pavi/.local/lib/python3.8/site-packages/django/core/handlers/exception.py", line 34, in inner
    response = get_response(request)
  File "/home/pavi/.local/lib/python3.8/site-packages/django/core/handlers/base.py", line 115, in _get_response
    response = self.process_exception_by_middleware(e, request)
  File "/home/pavi/.local/lib/python3.8/site-packages/django/core/handlers/base.py", line 113, in _get_response
    response = wrapped_callback(request, *callback_args, **callback_kwargs)
  File "/home/pavi/.local/lib/python3.8/site-packages/django/views/decorators/csrf.py", line 54, in wrapped_view
    return view_func(*args, **kwargs)
  File "/home/pavi/.local/lib/python3.8/site-packages/rest_framework/viewsets.py", line 114, in view
    return self.dispatch(request, *args, **kwargs)
  File "/home/pavi/.local/lib/python3.8/site-packages/rest_framework/views.py", line 507, in dispatch
    self.response = self.finalize_response(request, response, *args, **kwargs)
  File "/home/pavi/.local/lib/python3.8/site-packages/rest_framework/views.py", line 419, in finalize_response
    assert isinstance(response, HttpResponseBase), (
AssertionError: Expected a `Response`, `HttpResponse` or `HttpStreamingResponse` to be returned from the view, but received a `<class 'NoneType'>`
2022-03-23 11:20:58,804 ERROR "POST /api/copyright/ HTTP/1.1" 500 92721
2022-03-23 11:28:44,321 ERROR Internal Server Error: /api/copyright/
Traceback (most recent call last):
  File "/home/pavi/.local/lib/python3.8/site-packages/django/core/handlers/exception.py", line 34, in inner
    response = get_response(request)
  File "/home/pavi/.local/lib/python3.8/site-packages/django/core/handlers/base.py", line 115, in _get_response
    response = self.process_exception_by_middleware(e, request)
  File "/home/pavi/.local/lib/python3.8/site-packages/django/core/handlers/base.py", line 113, in _get_response
    response = wrapped_callback(request, *callback_args, **callback_kwargs)
  File "/home/pavi/.local/lib/python3.8/site-packages/django/views/decorators/csrf.py", line 54, in wrapped_view
    return view_func(*args, **kwargs)
  File "/home/pavi/.local/lib/python3.8/site-packages/rest_framework/viewsets.py", line 114, in view
    return self.dispatch(request, *args, **kwargs)
  File "/home/pavi/.local/lib/python3.8/site-packages/rest_framework/views.py", line 507, in dispatch
    self.response = self.finalize_response(request, response, *args, **kwargs)
  File "/home/pavi/.local/lib/python3.8/site-packages/rest_framework/views.py", line 419, in finalize_response
    assert isinstance(response, HttpResponseBase), (
AssertionError: Expected a `Response`, `HttpResponse` or `HttpStreamingResponse` to be returned from the view, but received a `<class 'NoneType'>`
2022-03-23 11:28:44,322 ERROR "POST /api/copyright/ HTTP/1.1" 500 92721
2022-03-23 11:29:59,283 ERROR Internal Server Error: /api/copyright/
Traceback (most recent call last):
  File "/home/pavi/.local/lib/python3.8/site-packages/django/core/handlers/exception.py", line 34, in inner
    response = get_response(request)
  File "/home/pavi/.local/lib/python3.8/site-packages/django/core/handlers/base.py", line 115, in _get_response
    response = self.process_exception_by_middleware(e, request)
  File "/home/pavi/.local/lib/python3.8/site-packages/django/core/handlers/base.py", line 113, in _get_response
    response = wrapped_callback(request, *callback_args, **callback_kwargs)
  File "/home/pavi/.local/lib/python3.8/site-packages/django/views/decorators/csrf.py", line 54, in wrapped_view
    return view_func(*args, **kwargs)
  File "/home/pavi/.local/lib/python3.8/site-packages/rest_framework/viewsets.py", line 114, in view
    return self.dispatch(request, *args, **kwargs)
  File "/home/pavi/.local/lib/python3.8/site-packages/rest_framework/views.py", line 507, in dispatch
    self.response = self.finalize_response(request, response, *args, **kwargs)
  File "/home/pavi/.local/lib/python3.8/site-packages/rest_framework/views.py", line 419, in finalize_response
    assert isinstance(response, HttpResponseBase), (
AssertionError: Expected a `Response`, `HttpResponse` or `HttpStreamingResponse` to be returned from the view, but received a `<class 'NoneType'>`
2022-03-23 11:29:59,283 ERROR "POST /api/copyright/ HTTP/1.1" 500 92721
